<?xml version="1.0" encoding="utf-8"?>
<!-- This URDF was automatically created by SolidWorks to URDF Exporter! Originally created by Stephen Brawner (brawner@gmail.com) 
     Commit Version: 1.6.0-4-g7f85cfe  Build Version: 1.6.7995.38578
     For more information, please see http://wiki.ros.org/sw_urdf_exporter -->
<robot
  name="proxima_manipulator">
  
  <link name="world"/>
  <joint name="base_joint" type="fixed">
    <parent link="world"/>
    <child link="base_link"/>
    <origin rpy="0 0 3.142" xyz="0.0 0.0 0.0"/>
    </joint>
  
  <link
    name="base_link">
    <inertial>
      <origin
        xyz="5.89900924100442E-07 -5.82635127656639E-07 0.0844077193187946"
        rpy="0 0 0" />
      <mass
        value="1.14715214327679" />
      <inertia
        ixx="0.00297605346011453"
        ixy="-1.28898690956909E-07"
        ixz="-2.94048693205158E-08"
        iyy="0.00297587811058845"
        iyz="3.89686890063112E-08"
        izz="0.00362946503703709" />
    </inertial>
    <visual>
      <origin
        xyz="0 0 0"
        rpy="0 0 0" />
      <geometry>
        <mesh
          filename="package://proxima_manipulator/meshes/base_link.STL" />
      </geometry>
      <material
        name="">
        <color
          rgba="0.792156862745098 0.819607843137255 0.933333333333333 1" />
      </material>
    </visual>
    <collision>
      <origin
        xyz="0 0 0"
        rpy="0 0 0" />
      <geometry>
        <mesh
          filename="package://proxima_manipulator/meshes/base_link.STL" />
      </geometry>
    </collision>
  </link>
  <link
    name="link1">
    <inertial>
      <origin
        xyz="-0.02303554449658 0.0598261439960179 -0.00152128479536754"
        rpy="0 0 0" />
      <mass
        value="0.61136208657295" />
      <inertia
        ixx="0.000676546033753411"
        ixy="6.26097408187564E-05"
        ixz="3.12553110077658E-06"
        iyy="0.000696662466663964"
        iyz="4.15108216757231E-06"
        izz="0.000629760400233308" />
    </inertial>
    <visual>
      <origin
        xyz="0 0 0"
        rpy="0 0 0" />
      <geometry>
        <mesh
          filename="package://proxima_manipulator/meshes/link1.STL" />
      </geometry>
      <material
        name="">
        <color
          rgba="0.792156862745098 0.819607843137255 0.933333333333333 1" />
      </material>
    </visual>
    <collision>
      <origin
        xyz="0 0 0"
        rpy="0 0 0" />
      <geometry>
        <mesh
          filename="package://proxima_manipulator/meshes/link1.STL" />
      </geometry>
    </collision>
  </link>
  <joint
    name="joint1"
    type="revolute">
    <origin
      xyz="0 0 0.139"
      rpy="1.5707963267949 0 0.06638110906424" />
    <parent
      link="base_link" />
    <child
      link="link1" />
    <axis
      xyz="0 1 0" />
    <limit
      lower="0"
      upper="6.28"
      effort="300"
      velocity="3" />
  </joint>
  <link
    name="link2">
    <inertial>
      <origin
        xyz="-0.00216465968461942 -0.0472925206404818 0.230220242332757"
        rpy="0 0 0" />
      <mass
        value="0.38181439972666" />
      <inertia
        ixx="0.000941247684324127"
        ixy="-7.13786139180788E-06"
        ixz="3.91099754328085E-05"
        iyy="0.000840304873940375"
        iyz="0.000132624480798902"
        izz="0.000234385525945225" />
    </inertial>
    <visual>
      <origin
        xyz="0 0 0"
        rpy="0 0 0" />
      <geometry>
        <mesh
          filename="package://proxima_manipulator/meshes/link2.STL" />
      </geometry>
      <material
        name="">
        <color
          rgba="0.792156862745098 0.819607843137255 0.933333333333333 1" />
      </material>
    </visual>
    <collision>
      <origin
        xyz="0 0 0"
        rpy="0 0 0" />
      <geometry>
        <mesh
          filename="package://proxima_manipulator/meshes/link2.STL" />
      </geometry>
    </collision>
  </link>
  <joint
    name="joint2"
    type="revolute">
    <origin
      xyz="0 0.0935000000000001 0"
      rpy="1.36961712465034 0.0798053031468139 -3.07640848847956" />
    <parent
      link="link1" />
    <child
      link="link2" />
    <axis
      xyz="0.997797583094881 0 0.0663323689462047" />
    <limit
      lower="-1.48"
      upper="1.48"
      effort="300"
      velocity="3" />
  </joint>
  <link
    name="link3">
    <inertial>
      <origin
        xyz="-0.0100219656341276 0.246047292844653 0.0090796809436352"
        rpy="0 0 0" />
      <mass
        value="0.427190530217147" />
      <inertia
        ixx="0.000999064602408102"
        ixy="1.05015196942548E-05"
        ixz="6.12464858498111E-06"
        iyy="0.000228416018088118"
        iyz="-2.80475702692715E-05"
        izz="0.000912793058488037" />
    </inertial>
    <visual>
      <origin
        xyz="0 0 0"
        rpy="0 0 0" />
      <geometry>
        <mesh
          filename="package://proxima_manipulator/meshes/link3.STL" />
      </geometry>
      <material
        name="">
        <color
          rgba="0.792156862745098 0.819607843137255 0.933333333333333 1" />
      </material>
    </visual>
    <collision>
      <origin
        xyz="0 0 0"
        rpy="0 0 0" />
      <geometry>
        <mesh
          filename="package://proxima_manipulator/meshes/link3.STL" />
      </geometry>
    </collision>
  </link>
  <joint
    name="joint3"
    type="revolute">
    <origin
      xyz="-0.0252134458726865 -0.0783840441460631 0.379270569601745"
      rpy="2.99496503119234 -0.132055089452266 0.00971288768970507" />
    <parent
      link="link2" />
    <child
      link="link3" />
    <axis
      xyz="-0.997797583094835 0 -0.0663323689468866" />
    <limit
      lower="0"
      upper="2.96"
      effort="300"
      velocity="3" />
  </joint>
  <link
    name="link4">
    <inertial>
      <origin
        xyz="0.00636013910086945 6.35109644103737E-05 -0.0540678200298018"
        rpy="0 0 0" />
      <mass
        value="0.215390527753128" />
      <inertia
        ixx="0.000531350146196299"
        ixy="-7.37094030599829E-08"
        ixz="3.11549425204286E-05"
        iyy="0.000443875407065724"
        iyz="6.99835184177799E-07"
        izz="0.00011169485430132" />
    </inertial>
    <visual>
      <origin
        xyz="0 0 0"
        rpy="0 0 0" />
      <geometry>
        <mesh
          filename="package://proxima_manipulator/meshes/link4.STL" />
      </geometry>
      <material
        name="">
        <color
          rgba="0.792156862745098 0.819607843137255 0.933333333333333 1" />
      </material>
    </visual>
    <collision>
      <origin
        xyz="0 0 0"
        rpy="0 0 0" />
      <geometry>
        <mesh
          filename="package://proxima_manipulator/meshes/link4.STL" />
      </geometry>
    </collision>
  </link>
  <joint
    name="joint4"
    type="revolute">
    <origin
      xyz="-0.0010238 0.3878 0.0154"
      rpy="-2.9772 0.00089664 3.1307" />
    <parent
      link="link3" />
    <child
      link="link4" />
    <axis
      xyz="-0.99766 -0.00042801 -0.06837" />
    <limit
      lower="-2.84"
      upper="0"
      effort="300"
      velocity="3" />
  </joint>
  <link
    name="link5">
    <inertial>
      <origin
        xyz="0.00371786712021055 0.0233212511324778 -0.116194159187654"
        rpy="0 0 0" />
      <mass
        value="0.246635487348744" />
      <inertia
        ixx="0.000125362493056336"
        ixy="-4.92252749696487E-06"
        ixz="-1.17763756881474E-06"
        iyy="0.000175814678569274"
        iyz="-2.79929590483174E-07"
        izz="0.000136642700304457" />
    </inertial>
    <visual>
      <origin
        xyz="0 0 0"
        rpy="0 0 0" />
      <geometry>
        <mesh
          filename="package://proxima_manipulator/meshes/link5.STL" />
      </geometry>
      <material
        name="">
        <color
          rgba="0.792156862745098 0.819607843137255 0.933333333333333 1" />
      </material>
    </visual>
    <collision>
      <origin
        xyz="0 0 0"
        rpy="0 0 0" />
      <geometry>
        <mesh
          filename="package://proxima_manipulator/meshes/link5.STL" />
      </geometry>
    </collision>
  </link>
  <joint
    name="joint5"
    type="revolute">
    <origin
      xyz="0.00785440188739083 0.000169987875987765 -0.0683995354267096"
      rpy="0.0054593051623277 0.000428982055095075 -0.0823393113788932" />
    <parent
      link="link4" />
    <child
      link="link5" />
    <axis
      xyz="0.0663321663033525 0.00247182816787439 -0.997794534851245" />
    <limit
      lower="0"
      upper="6.28"
      effort="300"
      velocity="3" />
  </joint>
  <link
    name="link6">
    <inertial>
      <origin
        xyz="-0.000152328366238796 0.00158515196790932 -6.19972051277284E-06"
        rpy="0 0 0" />
      <mass
        value="0.00360273828231165" />
      <inertia
        ixx="2.82282719153219E-07"
        ixy="-2.27094022502872E-08"
        ixz="6.44224708059163E-09"
        iyy="5.16678537642924E-07"
        iyz="-3.93868589772816E-10"
        izz="2.59870298318397E-07" />
    </inertial>
    <visual>
      <origin
        xyz="0 0 0"
        rpy="0 0 0" />
      <geometry>
        <mesh
          filename="package://proxima_manipulator/meshes/link6.STL" />
      </geometry>
      <material
        name="">
        <color
          rgba="0.792156862745098 0.819607843137255 0.933333333333333 1" />
      </material>
    </visual>
    <collision>
      <origin
        xyz="0 0 0"
        rpy="0 0 0" />
      <geometry>
        <mesh
          filename="package://proxima_manipulator/meshes/link6.STL" />
      </geometry>
    </collision>
  </link>
  <joint
    name="joint6"
    type="revolute">
    <origin
      xyz="0.012473 0.040866 -0.11678"
      rpy="-0.048992 0.46738 -0.013527" />
    <parent
      link="link5" />
    <child
      link="link6" />
    <axis
      xyz="-0.095656 0.99541 -0.0038932" />
    <limit
      lower="0"
      upper="3.14"
      effort="300"
      velocity="3" />
  </joint>

  <transmission name="tran1">
    <type>transmission_interface/SimpleTransmission</type>
     <joint name="joint1">
     <hardwareInterface>hardware_interface/PositionJointInterface</hardwareInterface>
     </joint>
     <actuator name="motor1">
     <hardwareInterface>hardware_interface/PositionJointInterface</hardwareInterface>
     <mechanicalReduction>1</mechanicalReduction>
     </actuator>
     </transmission>
 
     <transmission name="tran2">
    <type>transmission_interface/SimpleTransmission</type>
     <joint name="joint2">
     <hardwareInterface>hardware_interface/PositionJointInterface</hardwareInterface>
     </joint>
     <actuator name="motor2">
     <hardwareInterface>hardware_interface/PositionJointInterface</hardwareInterface>
     <mechanicalReduction>1</mechanicalReduction>
     </actuator>
     </transmission>
 
     <transmission name="tran3">
    <type>transmission_interface/SimpleTransmission</type>
     <joint name="joint3">
     <hardwareInterface>hardware_interface/PositionJointInterface</hardwareInterface>
     </joint>
     <actuator name="motor3">
     <hardwareInterface>hardware_interface/PositionJointInterface</hardwareInterface>
     <mechanicalReduction>1</mechanicalReduction>
     </actuator>
     </transmission>
 
     <transmission name="tran4">
    <type>transmission_interface/SimpleTransmission</type>
     <joint name="joint4">
     <hardwareInterface>hardware_interface/PositionJointInterface</hardwareInterface>
     </joint>
     <actuator name="motor4">
     <hardwareInterface>hardware_interface/PositionJointInterface</hardwareInterface>
     <mechanicalReduction>1</mechanicalReduction>
     </actuator>
     </transmission>
 
     <transmission name="tran5">
    <type>transmission_interface/SimpleTransmission</type>
     <joint name="joint5">
     <hardwareInterface>hardware_interface/PositionJointInterface</hardwareInterface>
     </joint>
     <actuator name="motor5">
     <hardwareInterface>hardware_interface/PositionJointInterface</hardwareInterface>
     <mechanicalReduction>1</mechanicalReduction>
     </actuator>
     </transmission>
 
     <transmission name="tran6">
    <type>transmission_interface/SimpleTransmission</type>
     <joint name="joint6">
     <hardwareInterface>hardware_interface/PositionJointInterface</hardwareInterface>
     </joint>
     <actuator name="motor6">
     <hardwareInterface>hardware_interface/PositionJointInterface</hardwareInterface>
     <mechanicalReduction>1</mechanicalReduction>
     </actuator>
     </transmission>
 
     <gazebo>
   <plugin name="gazebo_ros_control" filename="libgazebo_ros_control.so">
     <robotNamespace>/</robotNamespace>
   </plugin>
 </gazebo>
 
 <gazebo reference="link1">
   <selfCollide>true</selfCollide>
   </gazebo>
 
   <gazebo reference="link2">
   <selfCollide>true</selfCollide>
   </gazebo>
 
   <gazebo reference="link3">
   <selfCollide>true</selfCollide>
   </gazebo>
 
   <gazebo reference="link4">
   <selfCollide>true</selfCollide>
   </gazebo>
 
   <gazebo reference="link5">
   <selfCollide>true</selfCollide>
   </gazebo>
 
   <gazebo reference="link6">
   <selfCollide>true</selfCollide>
   </gazebo>
 
 
 </robot>